Workbook

Sheet How to use
A1: Campus Front-End L1 — Interview Question Bank (JavaScript)
A2: Source: EPAM KB › Campus Front-End L1 Competency Matrix (JS), last updated Jun 03, 2025. Skills, Skillo IDs and required levels copied from that page.
A3: Also includes self-check questions from EPAM KB › JS Competency Center › 1. Technical Skills [JS D2 Growth] (HTML, CSS, JavaScript, TypeScript, Angular, React.js, Node.js, Communication Protocols, Security), last updated Dec 08, 2024. The Source column shows where each question came from.
A5: Sheets
A6: Skills Overview — every skill in the matrix with its ID, required level, question count and average interview score (formulas).
A7: Question Bank — questions per skill with expected key points and follow-ups. Filter by Skill, Type or Difficulty.
A9: Columns to fill in during an interview (yellow cells in Question Bank)
A10: Score (0–3): leave blank if the question was not asked. Notes: free text.
A11: Example: Score = 2, Notes = "Explained bubbling well, unsure about capture option syntax"
A13: Scoring scale
A14: 0 — No answer / incorrect
A15: 1 — Partial: knows the term, can't explain or apply
... A29: Where the page shows two levels (e.g. TypeScript 'Novice / Intermediate'), both are kept as shown — the matrix is marked 'UPGRADE IN PROGRESS'.

Sheet Skills Overview
A1: # | B1: Skill | C1: Skillo ID | D1: Required Level (L1) | E1: Review Status | F1: Assessed at L1 | G1: Questions | H1: From L1 Matrix | I1: From D2 Growth | J1: Basic | K1: Core | L1: Stretch | M1: Questions scored | N1: Avg score (0–3)
A2: 1 | B2: HTML | C2: 7770000000000102564 | D2: Intermediate | E2: — | F2: Yes | G2: =COUNTIF('Question Bank'!$B$2:$B$424,B2) -> 29 | H2: =COUNTIFS('Question Bank'!$B$2:$B$424,B2,'Question Bank'!$C$2:$C$424,"L1 Matrix") -> 10 | I2: =COUNTIFS('Question Bank'!$B$2:$B$424,B2,'Question Bank'!$C$2:$C$424,"JS D2 Growth") -> 19 | J2: =COUNTIFS('Question Bank'!$B$2:$B$424,B2,'Question Bank'!$G$2:$G$424,"Basic") -> 17 | K2: =COUNTIFS('Question Bank'!$B$2:$B$424,B2,'Question Bank'!$G$2:$G$424,"Core") -> 12 | L2: =COUNTIFS('Question Bank'!$B$2:$B$424,B2,'Question Bank'!$G$2:$G$424,"Stretch") -> 0 | M2: =COUNTIFS('Question Bank'!$B$2:$B$424,B2,'Question Bank'!$K$2:$K$424,"<>") -> 0 | N2: =IFERROR(AVERAGEIF('Question Bank'!$B$2:$B$424,B2,'Question Bank'!$K$2:$K$424),"—") -> —
A3: 2 | B3: Frontend Web Accessibility | C3: 7770000000000100000 | D3: Novice | E3: APPROVED | F3: Yes | G3: =COUNTIF('Question Bank'!$B$2:$B$424,B3) -> 6 | H3: =COUNTIFS('Question Bank'!$B$2:$B$424,B3,'Question Bank'!$C$2:$C$424,"L1 Matrix") -> 6 | I3: =COUNTIFS('Question Bank'!$B$2:$B$424,B3,'Question Bank'!$C$2:$C$424,"JS D2 Growth") -> 0 | J3: =COUNTIFS('Question Bank'!$B$2:$B$424,B3,'Question Bank'!$G$2:$G$424,"Basic") -> 6 | K3: =COUNTIFS('Question Bank'!$B$2:$B$424,B3,'Question Bank'!$G$2:$G$424,"Core") -> 0 | L3: =COUNTIFS('Question Bank'!$B$2:$B$424,B3,'Question Bank'!$G$2:$G$424,"Stretch") -> 0 | M3: =COUNTIFS('Question Bank'!$B$2:$B$424,B3,'Question Bank'!$K$2:$K$424,"<>") -> 0 | N3: =IFERROR(AVERAGEIF('Question Bank'!$B$2:$B$424,B3,'Question Bank'!$K$2:$K$424),"—") -> —
A4: 3 | B4: CSS | C4: 7770000000000101404 | D4: Intermediate | E4: — | F4: Yes | G4: =COUNTIF('Question Bank'!$B$2:$B$424,B4) -> 33 | H4: =COUNTIFS('Question Bank'!$B$2:$B$424,B4,'Question Bank'!$C$2:$C$424,"L1 Matrix") -> 14 | I4: =COUNTIFS('Question Bank'!$B$2:$B$424,B4,'Question Bank'!$C$2:$C$424,"JS D2 Growth") -> 19 | J4: =COUNTIFS('Question Bank'!$B$2:$B$424,B4,'Question Bank'!$G$2:$G$424,"Basic") -> 13 | K4: =COUNTIFS('Question Bank'!$B$2:$B$424,B4,'Question Bank'!$G$2:$G$424,"Core") -> 17 | L4: =COUNTIFS('Question Bank'!$B$2:$B$424,B4,'Question Bank'!$G$2:$G$424,"Stretch") -> 3 | M4: =COUNTIFS('Question Bank'!$B$2:$B$424,B4,'Question Bank'!$K$2:$K$424,"<>") -> 0 | N4: =IFERROR(AVERAGEIF('Question Bank'!$B$2:$B$424,B4,'Question Bank'!$K$2:$K$424),"—") -> —
A5: 4 | B5: JavaScript | C5: 339 | D5: Intermediate | E5: — | F5: Yes | G5: =COUNTIF('Question Bank'!$B$2:$B$424,B5) -> 54 | H5: =COUNTIFS('Question Bank'!$B$2:$B$424,B5,'Question Bank'!$C$2:$C$424,"L1 Matrix") -> 33 | I5: =COUNTIFS('Question Bank'!$B$2:$B$424,B5,'Question Bank'!$C$2:$C$424,"JS D2 Growth") -> 21 | J5: =COUNTIFS('Question Bank'!$B$2:$B$424,B5,'Question Bank'!$G$2:$G$424,"Basic") -> 14 | K5: =COUNTIFS('Question Bank'!$B$2:$B$424,B5,'Question Bank'!$G$2:$G$424,"Core") -> 35 | L5: =COUNTIFS('Question Bank'!$B$2:$B$424,B5,'Question Bank'!$G$2:$G$424,"Stretch") -> 5 | M5: =COUNTIFS('Question Bank'!$B$2:$B$424,B5,'Question Bank'!$K$2:$K$424,"<>") -> 0 | N5: =IFERROR(AVERAGEIF('Question Bank'!$B$2:$B$424,B5,'Question Bank'!$K$2:$K$424),"—") -> —
A6: 5 | B6: TypeScript | C6: 7770000000000112280 | D6: Novice / Intermediate | E6: — | F6: Yes | G6: =COUNTIF('Question Bank'!$B$2:$B$424,B6) -> 36 | H6: =COUNTIFS('Question Bank'!$B$2:$B$424,B6,'Question Bank'!$C$2:$C$424,"L1 Matrix") -> 12 | I6: =COUNTIFS('Question Bank'!$B$2:$B$424,B6,'Question Bank'!$C$2:$C$424,"JS D2 Growth") -> 24 | J6: =COUNTIFS('Question Bank'!$B$2:$B$424,B6,'Question Bank'!$G$2:$G$424,"Basic") -> 17 | K6: =COUNTIFS('Question Bank'!$B$2:$B$424,B6,'Question Bank'!$G$2:$G$424,"Core") -> 16 | L6: =COUNTIFS('Question Bank'!$B$2:$B$424,B6,'Question Bank'!$G$2:$G$424,"Stretch") -> 3 | M6: =COUNTIFS('Question Bank'!$B$2:$B$424,B6,'Question Bank'!$K$2:$K$424,"<>") -> 0 | N6: =IFERROR(AVERAGEIF('Question Bank'!$B$2:$B$424,B6,'Question Bank'!$K$2:$K$424),"—") -> —
A7: 6 | B7: JavaScript Development Tools | C7: 7770000000000102295 | D7: Novice | E7: — | F7: Yes | G7: =COUNTIF('Question Bank'!$B$2:$B$424,B7) -> 5 | H7: =COUNTIFS('Question Bank'!$B$2:$B$424,B7,'Question Bank'!$C$2:$C$424,"L1 Matrix") -> 5 | I7: =COUNTIFS('Question Bank'!$B$2:$B$424,B7,'Question Bank'!$C$2:$C$424,"JS D2 Growth") -> 0 | J7: =COUNTIFS('Question Bank'!$B$2:$B$424,B7,'Question Bank'!$G$2:$G$424,"Basic") -> 5 | K7: =COUNTIFS('Question Bank'!$B$2:$B$424,B7,'Question Bank'!$G$2:$G$424,"Core") -> 0 | L7: =COUNTIFS('Question Bank'!$B$2:$B$424,B7,'Question Bank'!$G$2:$G$424,"Stretch") -> 0 | M7: =COUNTIFS('Question Bank'!$B$2:$B$424,B7,'Question Bank'!$K$2:$K$424,"<>") -> 0 | N7: =IFERROR(AVERAGEIF('Question Bank'!$B$2:$B$424,B7,'Question Bank'!$K$2:$K$424),"—") -> —
A8: 7 | B8: Browser APIs | C8: 7770000000000102876 | D8: Intermediate / Novice | E8: — | F8: Yes | G8: =COUNTIF('Question Bank'!$B$2:$B$424,B8) -> 9 | H8: =COUNTIFS('Question Bank'!$B$2:$B$424,B8,'Question Bank'!$C$2:$C$424,"L1 Matrix") -> 9 | I8: =COUNTIFS('Question Bank'!$B$2:$B$424,B8,'Question Bank'!$C$2:$C$424,"JS D2 Growth") -> 0 | J8: =COUNTIFS('Question Bank'!$B$2:$B$424,B8,'Question Bank'!$G$2:$G$424,"Basic") -> 3 | K8: =COUNTIFS('Question Bank'!$B$2:$B$424,B8,'Question Bank'!$G$2:$G$424,"Core") -> 6 | L8: =COUNTIFS('Question Bank'!$B$2:$B$424,B8,'Question Bank'!$G$2:$G$424,"Stretch") -> 0 | M8: =COUNTIFS('Question Bank'!$B$2:$B$424,B8,'Question Bank'!$K$2:$K$424,"<>") -> 0 | N8: =IFERROR(AVERAGEIF('Question Bank'!$B$2:$B$424,B8,'Question Bank'!$K$2:$K$424),"—") -> —
A9: 8 | B9: JavaScript in Browser | C9: 7770000000000116741 | D9: Novice / Intermediate | E9: — | F9: Yes | G9: =COUNTIF('Question Bank'!$B$2:$B$424,B9) -> 33 | H9: =COUNTIFS('Question Bank'!$B$2:$B$424,B9,'Question Bank'!$C$2:$C$424,"L1 Matrix") -> 13 | I9: =COUNTIFS('Question Bank'!$B$2:$B$424,B9,'Question Bank'!$C$2:$C$424,"JS D2 Growth") -> 20 | J9: =COUNTIFS('Question Bank'!$B$2:$B$424,B9,'Question Bank'!$G$2:$G$424,"Basic") -> 13 | K9: =COUNTIFS('Question Bank'!$B$2:$B$424,B9,'Question Bank'!$G$2:$G$424,"Core") -> 20 | L9: =COUNTIFS('Question Bank'!$B$2:$B$424,B9,'Question Bank'!$G$2:$G$424,"Stretch") -> 0 | M9: =COUNTIFS('Question Bank'!$B$2:$B$424,B9,'Question Bank'!$K$2:$K$424,"<>") -> 0 | N9: =IFERROR(AVERAGEIF('Question Bank'!$B$2:$B$424,B9,'Question Bank'!$K$2:$K$424),"—") -> —
A10: 9 | B10: JavaScript Top Frameworks | C10: 7770000000000117080 | D10: Intermediate | E10: — | F10: Yes | G10: =COUNTIF('Question Bank'!$B$2:$B$424,B10) -> 6 | H10: =COUNTIFS('Question Bank'!$B$2:$B$424,B10,'Question Bank'!$C$2:$C$424,"L1 Matrix") -> 6 | I10: =COUNTIFS('Question Bank'!$B$2:$B$424,B10,'Question Bank'!$C$2:$C$424,"JS D2 Growth") -> 0 | J10: =COUNTIFS('Question Bank'!$B$2:$B$424,B10,'Question Bank'!$G$2:$G$424,"Basic") -> 2 | K10: =COUNTIFS('Question Bank'!$B$2:$B$424,B10,'Question Bank'!$G$2:$G$424,"Core") -> 4 | L10: =COUNTIFS('Question Bank'!$B$2:$B$424,B10,'Question Bank'!$G$2:$G$424,"Stretch") -> 0 | M10: =COUNTIFS('Question Bank'!$B$2:$B$424,B10,'Question Bank'!$K$2:$K$424,"<>") -> 0 | N10: =IFERROR(AVERAGEIF('Question Bank'!$B$2:$B$424,B10,'Question Bank'!$K$2:$K$424),"—") -> —
A11: 10 | B11: ReactJS | C11: 7770000000000102668 | D11: Intermediate | E11: — | F11: Yes | G11: =COUNTIF('Question Bank'!$B$2:$B$424,B11) -> 34 | H11: =COUNTIFS('Question Bank'!$B$2:$B$424,B11,'Question Bank'!$C$2:$C$424,"L1 Matrix") -> 10 | I11: =COUNTIFS('Question Bank'!$B$2:$B$424,B11,'Question Bank'!$C$2:$C$424,"JS D2 Growth") -> 24 | J11: =COUNTIFS('Question Bank'!$B$2:$B$424,B11,'Question Bank'!$G$2:$G$424,"Basic") -> 11 | K11: =COUNTIFS('Question Bank'!$B$2:$B$424,B11,'Question Bank'!$G$2:$G$424,"Core") -> 20 | L11: =COUNTIFS('Question Bank'!$B$2:$B$424,B11,'Question Bank'!$G$2:$G$424,"Stretch") -> 3 | M11: =COUNTIFS('Question Bank'!$B$2:$B$424,B11,'Question Bank'!$K$2:$K$424,"<>") -> 0 | N11: =IFERROR(AVERAGEIF('Question Bank'!$B$2:$B$424,B11,'Question Bank'!$K$2:$K$424),"—") -> —
A12: 11 | B12: Angular | C12: 4060741400037627506 | D12: Intermediate | E12: — | F12: Yes | G12: =COUNTIF('Question Bank'!$B$2:$B$424,B12) -> 57 | H12: =COUNTIFS('Question Bank'!$B$2:$B$424,B12,'Question Bank'!$C$2:$C$424,"L1 Matrix") -> 13 | I12: =COUNTIFS('Question Bank'!$B$2:$B$424,B12,'Question Bank'!$C$2:$C$424,"JS D2 Growth") -> 44 | J12: =COUNTIFS('Question Bank'!$B$2:$B$424,B12,'Question Bank'!$G$2:$G$424,"Basic") -> 17 | K12: =COUNTIFS('Question Bank'!$B$2:$B$424,B12,'Question Bank'!$G$2:$G$424,"Core") -> 37 | L12: =COUNTIFS('Question Bank'!$B$2:$B$424,B12,'Question Bank'!$G$2:$G$424,"Stretch") -> 3 | M12: =COUNTIFS('Question Bank'!$B$2:$B$424,B12,'Question Bank'!$K$2:$K$424,"<>") -> 0 | N12: =IFERROR(AVERAGEIF('Question Bank'!$B$2:$B$424,B12,'Question Bank'!$K$2:$K$424),"—") -> —
A13: 12 | B13: CSS Preprocessors | C13: 7770000000000107664 | D13: Novice | E13: — | F13: Yes | G13: =COUNTIF('Question Bank'!$B$2:$B$424,B13) -> 7 | H13: =COUNTIFS('Question Bank'!$B$2:$B$424,B13,'Question Bank'!$C$2:$C$424,"L1 Matrix") -> 2 | I13: =COUNTIFS('Question Bank'!$B$2:$B$424,B13,'Question Bank'!$C$2:$C$424,"JS D2 Growth") -> 5 | J13: =COUNTIFS('Question Bank'!$B$2:$B$424,B13,'Question Bank'!$G$2:$G$424,"Basic") -> 6 | K13: =COUNTIFS('Question Bank'!$B$2:$B$424,B13,'Question Bank'!$G$2:$G$424,"Core") -> 1 | L13: =COUNTIFS('Question Bank'!$B$2:$B$424,B13,'Question Bank'!$G$2:$G$424,"Stretch") -> 0 | M13: =COUNTIFS('Question Bank'!$B$2:$B$424,B13,'Question Bank'!$K$2:$K$424,"<>") -> 0 | N13: =IFERROR(AVERAGEIF('Question Bank'!$B$2:$B$424,B13,'Question Bank'!$K$2:$K$424),"—") -> —
... A34: 33 | B34: Consultancy | C34: 7770000000000101790 | D34: None | E34: — | F34: No | G34: =COUNTIF('Question Bank'!$B$2:$B$424,B34) -> 0 | H34: =COUNTIFS('Question Bank'!$B$2:$B$424,B34,'Question Bank'!$C$2:$C$424,"L1 Matrix") -> 0 | I34: =COUNTIFS('Question Bank'!$B$2:$B$424,B34,'Question Bank'!$C$2:$C$424,"JS D2 Growth") -> 0 | J34: =COUNTIFS('Question Bank'!$B$2:$B$424,B34,'Question Bank'!$G$2:$G$424,"Basic") -> 0 | K34: =COUNTIFS('Question Bank'!$B$2:$B$424,B34,'Question Bank'!$G$2:$G$424,"Core") -> 0 | L34: =COUNTIFS('Question Bank'!$B$2:$B$424,B34,'Question Bank'!$G$2:$G$424,"Stretch") -> 0 | M34: =COUNTIFS('Question Bank'!$B$2:$B$424,B34,'Question Bank'!$K$2:$K$424,"<>") -> 0 | N34: =IFERROR(AVERAGEIF('Question Bank'!$B$2:$B$424,B34,'Question Bank'!$K$2:$K$424),"—") -> —
B35: Total | G35: =SUM(G2:G34) -> 423 | H35: =SUM(H2:H34) -> 194 | I35: =SUM(I2:I34) -> 229 | J35: =SUM(J2:J34) -> 210 | K35: =SUM(K2:K34) -> 191 | L35: =SUM(L2:L34) -> 22 | M35: =SUM(M2:M34) -> 0 | N35: =IFERROR(AVERAGE('Question Bank'!$K$2:$K$424),"—") -> —

Sheet Question Bank
A1: ID | B1: Skill | C1: Source | D1: Required Level | E1: Topic | F1: Type | G1: Difficulty | H1: Question | I1: Expected answer / key points | J1: Follow-up | K1: Score (0–3) | L1: Notes
A2: Q001 | B2: HTML | C2: L1 Matrix | D2: Intermediate | E2: Page structure | F2: Theory | G2: Basic | H2: What is the minimal structure of a valid HTML5 document? | I2: <!DOCTYPE html>, <html lang>, <head> with <meta charset> and <title>, <body>. Doctype switches browser to standards mode. | J2: What happens if the doctype is missing (quirks mode)?
A3: Q002 | B3: HTML | C3: L1 Matrix | D3: Intermediate | E3: DOM structure | F3: Theory | G3: Basic | H3: How does the browser turn HTML into the DOM? What is the tree model? | I3: Parser tokenizes markup and builds a node tree (document → elements, text, comment nodes); parent/child/sibling relations; DOM is a live object model, not the source text. | J3: How does the DOM differ from the HTML source after JS runs?
A4: Q003 | B4: HTML | C4: L1 Matrix | D4: Intermediate | E4: Semantic tags | F4: Theory | G4: Core | H4: Why use semantic HTML5 tags (header, nav, main, article, section, aside, footer) instead of divs? | I4: Meaning for assistive tech and SEO, landmark navigation, readability/maintainability; article = self-contained, section = thematic grouping with heading. | J4: When would you pick <article> over <section>?
A5: Q004 | B5: HTML | C5: L1 Matrix | D5: Intermediate | E5: Metadata, Styles, Scripts | F5: Theory | G5: Core | H5: What does <meta name="viewport"> do and why is it needed? | I5: Controls layout viewport on mobile: width=device-width, initial-scale=1; without it mobile browsers render at ~980px and scale down.
A6: Q005 | B6: HTML | C6: L1 Matrix | D6: Intermediate | E6: Metadata, Styles, Scripts | F6: Theory | G6: Core | H6: Explain the difference between <script>, <script async> and <script defer>. | I6: Plain blocks parsing; async downloads in parallel and executes as soon as ready (order not guaranteed); defer downloads in parallel, executes after parsing in document order. type=module is deferred by default. | J6: Where would you put an analytics script vs. your app bundle?
A7: Q006 | B7: HTML | C7: L1 Matrix | D7: Intermediate | E7: Metadata, Styles, Scripts | F7: Theory | G7: Basic | H7: What are the ways to include CSS in a page and their trade-offs? | I7: Inline style attribute, internal <style>, external <link rel=stylesheet>; external is cacheable/reusable; inline has highest specificity, hard to maintain.
A8: Q007 | B8: HTML | C8: L1 Matrix | D8: Intermediate | E8: Forms & Inputs | F8: Practical | G8: Core | H8: Build a login form with proper labels, input types and built-in validation. | I8: <form> with action/method, <label for> bound to id, type=email/password, required, minlength, autocomplete attributes, <button type=submit>. | J8: What's the difference between button type=submit and type=button?
A9: Q008 | B9: HTML | C9: L1 Matrix | D9: Intermediate | E9: Forms & Inputs | F9: Theory | G9: Core | H9: Name HTML5 input types and the benefit they bring. | I9: email, url, tel, number, range, date, time, color, search; native validation, mobile keyboards, built-in pickers.
A10: Q009 | B10: HTML | C10: L1 Matrix | D10: Intermediate | E10: Tables | F10: Theory | G10: Basic | H10: Which tags and attributes structure an accessible table? | I10: <table>, <caption>, <thead>/<tbody>/<tfoot>, <tr>, <th scope>, <td>, colspan/rowspan. Tables for tabular data, not layout.
A11: Q010 | B11: HTML | C11: L1 Matrix | D11: Intermediate | E11: Attributes | F11: Theory | G11: Basic | H11: What's the difference between global attributes like id, class, data-*, hidden, tabindex? | I11: id unique per page, class reusable for styling/selection, data-* for custom data (dataset in JS), hidden removes from rendering, tabindex controls focus order.
A12: Q011 | B12: HTML | C12: JS D2 Growth | D12: Intermediate | E12: Semantic elements | F12: Theory | G12: Basic | H12: Name HTML5 semantic elements and where you'd use them. | I12: header, nav, main, article, section, aside, footer, figure/figcaption, time, mark, details/summary; meaning for a11y/SEO.
A13: Q012 | B13: HTML | C13: JS D2 Growth | D13: Intermediate | E13: Validation | F13: Practical | G13: Basic | H13: How do you check HTML markup validity? | I13: W3C Markup Validator, IDE/linters (HTMLHint), DevTools issues panel, axe/Lighthouse for a11y-related markup problems.
A14: Q013 | B14: HTML | C14: JS D2 Growth | D14: Intermediate | E14: DOM interfaces | F14: Theory | G14: Core | H14: Where are EventTarget, Node, Element, HTMLElement and HTMLInputElement used? How are they related? | I14: Inheritance chain EventTarget → Node → Element → HTMLElement → HTMLInputElement; each adds API (events, tree, attributes, HTML props, input-specific value/checked).
A15: Q014 | B15: HTML | C15: JS D2 Growth | D15: Intermediate | E15: dataset | F15: Coding | G15: Basic | H15: What is the dataset attribute? Read and write data-* attributes from JS. | I15: data-user-id ↔ el.dataset.userId (camelCase), values are strings; useful for passing data to JS/CSS ([data-state]).
A16: Q015 | B16: HTML | C16: JS D2 Growth | D16: Intermediate | E16: async/defer | F16: Theory | G16: Core | H16: Describe how async and defer attributes work on <script>. | I16: async: parallel download, execute when ready, order not guaranteed; defer: parallel download, execute after parsing in order, before DOMContentLoaded.
A17: Q016 | B17: HTML | C17: JS D2 Growth | D17: Intermediate | E17: SVG | F17: Coding | G17: Basic | H17: Draw a simple image (e.g., a circle inside a square) using <svg>. | I17: <svg width viewBox><rect .../><circle cx cy r fill/></svg>; vector, scalable, styleable via CSS.
A18: Q017 | B18: HTML | C18: JS D2 Growth | D18: Intermediate | E18: Canvas vs SVG | F18: Theory | G18: Core | H18: Difference between <canvas> and <svg>; when to use each? | I18: SVG: retained DOM, vector, accessible, good for icons/charts with few elements; canvas: immediate-mode bitmap, JS-drawn, good for games/many objects/pixel manipulation.
A19: Q018 | B19: HTML | C19: JS D2 Growth | D19: Intermediate | E19: Doctype | F19: Theory | G19: Basic | H19: What is <!DOCTYPE> and why is it needed? | I19: Declares document type; triggers standards mode instead of quirks mode.
A20: Q019 | B20: HTML | C20: JS D2 Growth | D20: Intermediate | E20: Head | F20: Theory | G20: Basic | H20: What is <head> for and which tags can it contain? | I20: Metadata: title, meta (charset, viewport, description), link, style, script, base, noscript.
... A31: Q030 | B31: Frontend Web Accessibility | C31: L1 Matrix | D31: Novice | E31: a11y specifications | F31: Theory | G31: Basic | H31: What is WCAG and what do the POUR principles stand for? | I31: Web Content Accessibility Guidelines; Perceivable, Operable, Understandable, Robust; levels A/AA/AAA, AA is the usual target.
A32: Q031 | B32: Frontend Web Accessibility | C32: L1 Matrix | D32: Novice | E32: Semantic tags and roles | F32: Theory | G32: Basic | H32: What is ARIA and what is the 'first rule of ARIA'? | I32: Accessible Rich Internet Applications: roles, states, properties. First rule: use native semantic elements before adding ARIA. | J32: Give an example where ARIA is necessary (e.g., aria-expanded on a custom disclosure).
A33: Q032 | B33: Frontend Web Accessibility | C33: L1 Matrix | D33: Novice | E33: Assistive Technology | F33: Practical | G33: Basic | H33: How would you check a page works for keyboard-only users? | I33: Tab through everything, visible focus indicator, logical order, no keyboard traps, Enter/Space activate controls, skip link.
A34: Q033 | B34: Frontend Web Accessibility | C34: L1 Matrix | D34: Novice | E34: Testing tools | F34: Practical | G34: Basic | H34: Which tools would you use to test accessibility? | I34: Lighthouse, axe DevTools, WAVE, browser a11y tree inspector, screen readers (NVDA, VoiceOver, JAWS); automated tools catch only part of issues.
A35: Q034 | B35: Frontend Web Accessibility | C35: L1 Matrix | D35: Novice | E35: Semantic tags and roles | F35: Theory | G35: Basic | H35: Why is a <div onclick> worse than a <button>? | I35: No focusability, no keyboard activation, no role announced; button gives all of that for free.
A36: Q035 | B36: Frontend Web Accessibility | C36: L1 Matrix | D36: Novice | E36: a11y specifications | F36: Theory | G36: Basic | H36: What makes good alt text, and when should alt be empty? | I36: Describe purpose/content concisely; alt="" for decorative images so screen readers skip them; never omit alt.
A37: Q036 | B37: CSS | C37: L1 Matrix | D37: Intermediate | E37: Fundamentals | F37: Theory | G37: Basic | H37: Explain the box model and box-sizing: border-box. | I37: content + padding + border + margin; border-box makes width include padding and border, simplifying layout.
A38: Q037 | B38: CSS | C38: L1 Matrix | D38: Intermediate | E38: Fundamentals | F38: Theory | G38: Core | H38: How is specificity calculated and how does the cascade resolve conflicts? | I38: Origin/importance, then specificity (inline > id > class/attr/pseudo-class > type), then source order; !important overrides; :where() has zero specificity. | J38: Compute specificity of '#nav .item a:hover'.
A39: Q038 | B39: CSS | C39: L1 Matrix | D39: Intermediate | E39: Positioning | F39: Theory | G39: Core | H39: Explain static, relative, absolute, fixed and sticky positioning. | I39: Static default; relative offsets from itself and creates containing block; absolute relative to nearest positioned ancestor; fixed to viewport; sticky toggles between relative and fixed within scroll container.
A40: Q039 | B40: CSS | C40: L1 Matrix | D40: Intermediate | E40: Overflow & z-index | F40: Theory | G40: Core | H40: Why might z-index: 9999 not put an element on top? | I40: Stacking contexts: z-index only competes within the same context; contexts are created by positioned+z-index, opacity<1, transform, filter, etc.
A41: Q040 | B41: CSS | C41: L1 Matrix | D41: Intermediate | E41: Flexbox | F41: Practical | G41: Core | H41: Center an element horizontally and vertically in a container with Flexbox and with Grid. | I41: Flex: display:flex; justify-content:center; align-items:center. Grid: display:grid; place-items:center.
A42: Q041 | B42: CSS | C42: L1 Matrix | D42: Intermediate | E42: Flexbox | F42: Theory | G42: Core | H42: Explain flex-grow, flex-shrink and flex-basis (the flex shorthand). | I42: basis = initial size, grow = share of free space, shrink = share of negative space; flex:1 = 1 1 0%. | J42: What does flex: none do?
A43: Q042 | B43: CSS | C43: L1 Matrix | D43: Intermediate | E43: Grid | F43: Practical | G43: Core | H43: Build a responsive card grid without media queries. | I43: grid-template-columns: repeat(auto-fit, minmax(240px, 1fr)); gap. Explain auto-fit vs auto-fill.
A44: Q043 | B44: CSS | C44: L1 Matrix | D44: Intermediate | E44: Flex vs Grid | F44: Theory | G44: Core | H44: When do you choose Flexbox vs Grid? | I44: Flex is one-dimensional, content-driven; Grid is two-dimensional, layout-driven; often combined.
A45: Q044 | B45: CSS | C45: L1 Matrix | D45: Intermediate | E45: Custom properties | F45: Theory | G45: Core | H45: How do CSS custom properties differ from preprocessor variables? | I45: Runtime, cascade and inherit, can be changed by JS and media queries, scoped to elements; Sass variables are compile-time. | J45: Implement light/dark theming with custom properties.
A46: Q045 | B46: CSS | C46: L1 Matrix | D46: Intermediate | E46: Logical functions | F46: Theory | G46: Core | H46: What do min(), max() and clamp() do? Give a fluid typography example. | I46: clamp(min, preferred, max), e.g. font-size: clamp(1rem, 2.5vw, 2rem).
A47: Q046 | B47: CSS | C47: L1 Matrix | D47: Intermediate | E47: Performance / Core Web Vitals | F47: Theory | G47: Stretch | H47: Which CSS properties are cheap to animate and which cause layout or paint? | I47: transform and opacity are compositor-only; width/top/margin trigger layout; color/background trigger paint. will-change hints. Avoid layout shifts (CLS).
A48: Q047 | B48: CSS | C48: L1 Matrix | D48: Intermediate | E48: Font loading | F48: Theory | G48: Stretch | H48: What font loading strategies do you know? | I48: font-display (swap, optional, fallback), preload critical fonts, subset, WOFF2, size-adjust fallbacks to reduce CLS.
A49: Q048 | B49: CSS | C49: L1 Matrix | D49: Intermediate | E49: Aspect-ratio / content-visibility | F49: Theory | G49: Stretch | H49: What problems do aspect-ratio and content-visibility + contain-intrinsic-size solve? | I49: aspect-ratio reserves space (no CLS); content-visibility:auto skips rendering off-screen content, contain-intrinsic-size gives placeholder size.
A50: Q049 | B50: CSS | C50: L1 Matrix | D50: Intermediate | E50: Browser compatibility | F50: Practical | G50: Core | H50: How do you handle a CSS feature not supported in a target browser? | I50: Check caniuse, @supports feature queries, progressive enhancement / fallbacks, autoprefixer/PostCSS, browserslist.
...
